<?xml version="1.0"?>

<robot xmlns:xacro="http://www.ros.org/wiki/xacro">
  <xacro:property name="PI" value="3.1415926535897931" />
  <xacro:property name="mass_2" value="0.093195" />
  <xacro:property name="cyl_r" value="0.0335" />
  <xacro:property name="cyl_h_in" value="0.03" />
  <xacro:property name="cyl_h_out" value="0.03" />

  <xacro:macro name="rotary_module_in" params="name">
    <link name="${name}">
      <visual>
	      <origin xyz="0 -0.00235 0.019" rpy="${-PI/2.0} 0 0" />
        <geometry>
          <mesh filename="package://snake_control/meshes/rotary_module_in.dae"/>
        </geometry>
        <xacro:red_material/>
      </visual>
    <collision>
      <origin xyz="0 0 0" rpy="0 0 0" />
      <geometry>
	<cylinder radius="${cyl_r}" length="${cyl_h_in}" />
      </geometry>
    </collision> 
    <inertial>
      <origin xyz="0 0 0" rpy="0 0 0" />
      <mass value="${mass_2}"/>
      <inertia ixx="${mass_2/12.0*(3*cyl_r**2+cyl_h_in**2)+mass_2*(cyl_h_in/2.0)**2}" iyy="${mass_2/12.0*(3*cyl_r**2+cyl_h_in**2)+mass_2*(cyl_h_in/2.0)**2}" izz="${mass_2/2.0*cyl_r**2}" ixy="0" ixz="0" iyz="0" />
    </inertial>
    </link>
  </xacro:macro>

  <xacro:macro name="rotary_module_joint" params="parent name child">

    <joint name="${name}" type="revolute">
      <parent link="${parent}"/>
      <child link="${child}"/>
      <origin xyz="0 0 0.02575" rpy="0 0 0"/>
      <axis xyz="0 1 0"/>
      <dynamics damping=".1" friction="0.2"/>
      <limit effort="7.0" lower="-1.57" upper="1.57" velocity="2.208932"/>
    </joint>

    <transmission name="${name}_trans">
      <type>transmission_interface/SimpleTransmission</type>
      <joint name="${name}">
	<hardwareInterface>EffortJointInterface</hardwareInterface>
      </joint>
      <actuator name="${name}_motor">
	<hardwareInterface>EffortJointInterface</hardwareInterface>
	<mechanicalReduction>300</mechanicalReduction>
      </actuator>
    </transmission>

  </xacro:macro>

  <xacro:macro name="rotary_module_out" params="name">
    <link name="${name}">
      <visual>
        <origin xyz="0 0.00225 0.0179" rpy="${-PI/2.0} 0 0" />
        <geometry>
          <mesh filename="package://snake_control/meshes/rotary_module_out.dae"/>
	  <!-- <cylinder radius=".0025" length=".1" /> -->
        </geometry>
        <xacro:red_material/>
      </visual>
    <collision>
      <origin xyz="0 0 0" rpy="0 0 0" />
      <geometry>
	<cylinder radius="${cyl_r}" length="${cyl_h_out}" />
      </geometry>
    </collision> 
    <inertial>
      <origin xyz="0 0 0" rpy="0 0 0" />
      <mass value="${mass_2}"/>
      <inertia ixx="${mass_2/12.0*(3*cyl_r**2+cyl_h_out**2)+mass_2*(cyl_h_out/2.0)**2}" iyy="${mass_2/12.0*(3*cyl_r**2+cyl_h_out**2)+mass_2*(cyl_h_out/2.0)**2}" izz="${mass_2/2.0*cyl_r**2}" ixy="0" ixz="0" iyz="0" />
    </inertial>
    </link>
  </xacro:macro>

  <xacro:macro name="rotary_module_out_interface" params="parent name child">
    <joint name="${name}" type="fixed">
      <parent link="${parent}"/>
      <child link="${child}"/>
      <origin xyz="0 0 0.036" rpy="0 0 -1.57075"/>
    </joint>
  </xacro:macro>

  <!-- NOTE: joint must match the name of the module -->
  <xacro:macro name="rotary_module" params="joint child">
    <!-- first half of joint + collar -->
    <xacro:rotary_module_in name="${joint}__INPUT_INTERFACE"/>
    <xacro:collar parent="${joint}__INPUT_INTERFACE"/>
    <!-- actual rotary joint component: -->
    <xacro:rotary_module_joint parent="${joint}__INPUT_INTERFACE" name="${joint}" child="${joint}__OUTPUT_BODY"/>
    <!-- second half of joint -->
    <xacro:rotary_module_out name="${joint}__OUTPUT_BODY"/>
    <!-- 90* turn at interface: -->
    <xacro:rotary_module_out_interface parent="${joint}__OUTPUT_BODY" name="${joint}__OUTPUT_INTERFACE" child="${child}__INPUT_INTERFACE"/>
  </xacro:macro>
</robot>
